from py42.settings import debug


class Py42Error(Exception):
    """A generic, Py42 custom base exception."""


class Py42ResponseError(Py42Error):
    """A base custom class to manage all errors raised because of an HTTP response."""

    def __init__(self, response, message):
        super().__init__(message)
        self._response = response

    @property
    def response(self):
        """The response prior to the error."""
        return self._response


class Py42ArchiveFileNotFoundError(Py42ResponseError):
    """An exception raised when a resource file is not found or the path is invalid."""

    def __init__(self, response, device_guid, file_path):
        message = (
            f"File not found in archive for device {device_guid} at path {file_path}"
        )
        super().__init__(response, message)


class Py42ChecksumNotFoundError(Py42ResponseError):
    """An exception raised when a user-supplied hash could not successfully locate its corresponding resource."""

    def __init__(self, response, checksum_name, checksum_value):
        message = f"No files found with {checksum_name} checksum {checksum_value}."
        super().__init__(response, message)


class Py42FeatureUnavailableError(Py42ResponseError):
    """An exception raised when a requested feature is not supported in your Code42 environment."""

    def __init__(self, response):
        super().__init__(
            response,
            "You may be trying to use a feature that is unavailable in your environment.",
        )


class Py42HTTPError(Py42ResponseError):
    """A base custom class to manage all HTTP errors raised by an API endpoint."""

    def __init__(self, exception, message=None):
        if not message:
            response_content = f"Response content: {exception.response.text}"
            message = f"Failure in HTTP call {exception}. {response_content}"
            debug.logger.debug(message)

        super().__init__(exception.response, message)


class Py42DeviceNotConnectedError(Py42ResponseError):
    """An exception raised when trying to push a restore to a device that is not
    connected to an Authority server."""

    def __init__(self, response, device_guid):
        message = (
            f"Device with GUID '{device_guid}' is not currently connected to the Authority "
            "server."
        )
        super().__init__(response, message)


class Py42InvalidArchivePassword(Py42HTTPError):
    """An exception raised when the password for unlocking an archive is invalid."""

    def __init__(self, exception):
        message = "Invalid archive password."
        super().__init__(exception, message)


class Py42InvalidArchiveEncryptionKey(Py42HTTPError):
    """An exception raised the encryption key for an archive is invalid."""

    def __init__(self, exception):
        message = "Invalid archive encryption key."
        super().__init__(exception, message)


class Py42StorageSessionInitializationError(Py42HTTPError):
    """An exception raised when the user is not authorized to initialize a storage session. This
    may occur when trying to restore a file or trying to get events for file activity on removable
    media, in cloud sync folders, and browser uploads."""

    def __init__(self, exception, error_message):
        super().__init__(exception, error_message)


class Py42SessionInitializationError(Py42Error):
    """An exception raised when a user connection is invalid. A connection might be invalid due to
    connection timeout, invalid token, etc.
    """

    def __init__(self, exception):
        error_message = (
            "An error occurred while requesting "
            f"server environment information, caused by {exception}"
        )
        super().__init__(exception, error_message)


class Py42BadRequestError(Py42HTTPError):
    """A wrapper to represent an HTTP 400 error."""


class Py42UnauthorizedError(Py42HTTPError):
    """A wrapper to represent an HTTP 401 error."""


class Py42ForbiddenError(Py42HTTPError):
    """A wrapper to represent an HTTP 403 error."""


class Py42NotFoundError(Py42HTTPError):
    """A wrapper to represent an HTTP 404 error."""


class Py42ConflictError(Py42HTTPError):
    """A wrapper to represent an HTTP 409 error."""


class Py42InternalServerError(Py42HTTPError):
    """A wrapper to represent an HTTP 500 error."""


class Py42TooManyRequestsError(Py42HTTPError):
    """A wrapper to represent an HTTP 429 error."""


class Py42OrgNotFoundError(Py42BadRequestError):
    """An exception raised when a 400 HTTP error message indicates that an
    organization was not found."""

    def __init__(self, exception, org_uid):
        msg = f"The organization with UID '{org_uid}' was not found."
        super().__init__(exception, msg)


class Py42ActiveLegalHoldError(Py42BadRequestError):
    """An exception raised when attempting to deactivate a user or device that is in an
    active legal hold."""

    def __init__(self, exception, resource, resource_id):
        msg = f"Cannot deactivate the {resource} with ID {resource_id} as the {resource} is involved in a legal hold matter."
        super().__init__(exception, msg)


class Py42UserAlreadyAddedError(Py42BadRequestError):
    """An exception raised when the user is already added to group or list, such as the
    Departing Employee list."""

    def __init__(self, exception, user_id, list_name):
        msg = f"User with ID {user_id} is already on the {list_name}."
        super().__init__(exception, msg)


class Py42LegalHoldNotFoundOrPermissionDeniedError(Py42ForbiddenError):
    """An exception raised when a legal hold matter is inaccessible from your account or
    the matter ID is not valid."""

    def __init__(self, exception, matter_id):
        super().__init__(
            exception,
            f"Matter with ID={matter_id} can not be found. Your account may not have permission to view the matter.",
        )


class Py42LegalHoldCriteriaMissingError(Py42BadRequestError):
    """An exception raised when a bad request was made to a Legal Hold endpoint."""

    def __init__(self, exception):
        super().__init__(
            exception,
            "At least one criteria must be specified; legal_hold_membership_uid, "
            "legal_hold_uid, user_uid, or user.",
        )


class Py42InvalidRuleOperationError(Py42HTTPError):
    """An exception raised when trying to add or remove users to a system rule."""

    def __init__(self, exception, rule_id, source):
        msg = "Only alert rules with a source of 'Alerting' can be targeted by this command. "
        msg += f"Rule {rule_id} has a source of '{source}'."
        super().__init__(exception, msg)


class Py42MFARequiredError(Py42UnauthorizedError):
    """Deprecated: An exception raised when a request requires multi-factor authentication"""

    def __init__(self, exception, message=None):
        message = message or "User requires multi-factor authentication."
        super().__init__(exception, message)


class Py42UserAlreadyExistsError(Py42InternalServerError):
    """An exception raised when a user already exists"""

    def __init__(self, exception, message=None):
        message = message or "User already exists."
        super().__init__(exception, message)


class Py42UsernameMustBeEmailError(Py42InternalServerError):
    """An exception raised when trying to set a non-email as a user's username
    in a cloud environment."""

    def __init__(self, exception):
        message = "Username must be an email address."
        super().__init__(exception, message)


class Py42InvalidEmailError(Py42InternalServerError):
    """An exception raised when trying to set an invalid email as a user's email."""

    def __init__(self, email, exception):
        message = f"'{email}' is not a valid email."
        super().__init__(exception, message)


class Py42InvalidPasswordError(Py42InternalServerError):
    """An exception raised when trying to set an invalid password as a user's password."""

    def __init__(self, exception):
        message = "Invalid password."
        super().__init__(exception, message)


class Py42InvalidUsernameError(Py42InternalServerError):
    """An exception raised when trying to set an invalid username as a user's username."""

    def __init__(self, exception):
        message = "Invalid username."
        super().__init__(exception, message)


class Py42CloudAliasLimitExceededError(Py42BadRequestError):
    """An Exception raised when trying to add a cloud alias to a user when that user
    already has the max amount of supported cloud aliases."""

    def __init__(self, exception, message=None):
        message = message or "Cloud alias limit exceeded."
        super(Py42BadRequestError, self).__init__(exception, message)


class Py42BadRestoreRequestError(Py42BadRequestError):
    """An error raised when the given restore arguments are not compatible and cause
    a bad request."""

    def __init__(self, exception):
        message = "Unable to create restore session."
        super().__init__(exception, message)


class Py42InvalidPageTokenError(Py42BadRequestError):
    """An error raised when the page token given is invalid."""

    def __init__(self, exception, page_token):
        message = f'Invalid page token: "{page_token}".'
        super().__init__(exception, message)


class Py42UserNotOnListError(Py42NotFoundError):
    """An exception raised when the user is not on a detection list."""

    def __init__(self, exception, user_id, list_name):
        message = f"User with ID '{user_id}' is not currently on the {list_name} list."
        super(Py42NotFoundError, self).__init__(exception, message)


class Py42UnableToCreateProfileError(Py42BadRequestError):
    """An error raised when trying to call the method for creating a detection-list
    user when the user does not exist or is currently awaiting the profile to get
    created on the back-end. Note: you are no longer able to create detection-list
    profiles using the API; py42 only returns already existing profiles."""

    def __init__(self, exception, username):
        message = (
            "Detection-list profiles are now created automatically on the server. "
            f"Unable to find a detection-list profile for '{username}'. "
            "It is possibly still being created if you just recently created the "
            "Code42 user."
        )
        super().__init__(exception, message)


class Py42InvalidRuleError(Py42NotFoundError):
    """An exception raised when the observer rule ID does not exist."""

    def __init__(self, exception, rule_id):
        message = f"Invalid Observer Rule ID '{rule_id}'."
        super(Py42NotFoundError, self).__init__(exception, message)


class Py42UpdateClosedCaseError(Py42BadRequestError):
    """An error raised when trying to update a closed case."""

    def __init__(self, exception):
        msg = "Cannot update a closed case."
        super().__init__(exception, msg)


class Py42CaseNameExistsError(Py42BadRequestError):
    """An error raised when trying to create a case with a name that already exists."""

    def __init__(self, exception, case_name):
        msg = f"Case name '{case_name}' already exists, please set another name."
        super().__init__(exception, msg)


class Py42DescriptionLimitExceededError(Py42BadRequestError):
    """An error raised when description of a case exceeds the allowed char length limit."""

    def __init__(self, exception):
        msg = "Description limit exceeded, max 250 characters allowed."
        super().__init__(exception, msg)


class Py42InvalidCaseUserError(Py42BadRequestError):
    """An error raised when a case subject or assignee is not a valid user."""

    def __init__(self, exception, user_field):
        msg = f"The provided {user_field} is not a valid user."
        super().__init__(exception, msg)


class Py42CaseAlreadyHasEventError(Py42BadRequestError):
    """An error raised when event is already associated to the case."""

    def __init__(self, exception):
        msg = "Event is already associated to the case."
        super().__init__(exception, msg)


class Py42TrustedActivityInvalidChangeError(Py42BadRequestError):
    """An error raised when an invalid change is being made to a trusted activity."""

    def __init__(self, exception):
        msg = "Invalid change to trusted activity. Trusted activity type cannot be changed."
        super().__init__(exception, msg)


class Py42TrustedActivityConflictError(Py42ConflictError):
    """An error raised when theres a conflict with a trusted activity domain URL."""

    def __init__(self, exception, value):
        msg = (
            f"Duplicate URL or workspace name, '{value}' already exists on your trusted list.  "
            "Please provide a unique value"
        )
        super().__init__(exception, msg)


class Py42TrustedActivityInvalidCharacterError(Py42BadRequestError):
    """An error raised when an invalid character is in a trusted activity value."""

    def __init__(self, exception):
        msg = "Invalid character in domain or slack workspace name"
        super().__init__(exception, msg)


class Py42TrustedActivityIdNotFound(Py42NotFoundError):
    """An exception raised when the trusted activity ID does not exist."""

    def __init__(self, exception, resource_id):
        message = f"Resource ID '{resource_id}' not found."
        super(Py42NotFoundError, self).__init__(exception, message)


def raise_py42_error(raised_error):
    """Raises the appropriate :class:`py42.exceptions.Py42HttpError` based on the given
    HTTPError's response status code.
    """
    if raised_error.response.status_code == 400:
        raise Py42BadRequestError(raised_error)
    elif raised_error.response.status_code == 401:
        raise Py42UnauthorizedError(raised_error)
    elif raised_error.response.status_code == 403:
        raise Py42ForbiddenError(raised_error)
    elif raised_error.response.status_code == 404:
        raise Py42NotFoundError(raised_error)
    elif raised_error.response.status_code == 409:
        raise Py42ConflictError(raised_error)
    elif raised_error.response.status_code == 429:
        raise Py42TooManyRequestsError(raised_error)
    elif 500 <= raised_error.response.status_code < 600:
        raise Py42InternalServerError(raised_error)
    else:
        raise Py42HTTPError(raised_error)
